outputs/states_InventoryAndVolatilityAdjusted_BuyPressure.csv
timestamp,strategy,regime,fair_price,best_bid,best_ask,recent_volatility,inventory,cash,pnl,bid_depth,ask_depth
1,InventoryAndVolatilityAdjusted,BuyPressure,100.000389,99.950000,100.050000,0.000023,0,0.000000,0.000000,1015,1000
2,InventoryAndVolatilityAdjusted,BuyPressure,99.989663,99.950000,100.050000,0.000665,0,0.000000,0.000000,997,1000
3,InventoryAndVolatilityAdjusted,BuyPressure,99.988038,99.960506,100.050000,0.000723,0,0.000000,0.000000,1006,1000
4,InventoryAndVolatilityAdjusted,BuyPressure,99.995666,99.960506,100.050000,0.001137,0,0.000000,0.000000,1006,988
5,InventoryAndVolatilityAdjusted,BuyPressure,100.004037,99.960506,100.050000,0.001571,0,0.000000,0.000000,1006,973
6,InventoryAndVolatilityAdjusted,BuyPressure,100.003717,99.960506,100.050000,0.001496,0,0.000000,0.000000,1006,988
7,InventoryAndVolatilityAdjusted,BuyPressure,100.001188,99.960506,100.050000,0.001558,0,0.000000,0.000000,1010,988
8,InventoryAndVolatilityAdjusted,BuyPressure,99.989382,99.960506,100.050000,0.002173,0,0.000000,0.000000,1007,988
9,InventoryAndVolatilityAdjusted,BuyPressure,99.997459,99.960506,100.050000,0.002527,0,0.000000,0.000000,1007,969
10,InventoryAndVolatilityAdjusted,BuyPressure,99.982073,99.950000,100.037021,0.003299,0,0.000000,0.000000,1001,979
11,InventoryAndVolatilityAdjusted,BuyPressure,99.995807,99.950000,100.050015,0.003925,-10,1000.370214,0.412139,1001,964
12,InventoryAndVolatilityAdjusted,BuyPressure,100.007907,99.950000,100.100000,0.004415,-10,1000.370214,0.291142,1001,947
13,InventoryAndVolatilityAdjusted,BuyPressure,100.015481,99.950000,100.100000,0.004605,-10,1000.370214,0.215403,1001,945
14,InventoryAndVolatilityAdjusted,BuyPressure,100.032291,99.950000,100.100000,0.005337,-10,1000.370214,0.047306,1001,942
15,InventoryAndVolatilityAdjusted,BuyPressure,100.036354,99.950000,100.100000,0.005261,-10,1000.370214,0.006675,1001,944
16,InventoryAndVolatilityAdjusted,BuyPressure,100.040872,99.959591,100.100000,0.005216,-10,1000.370214,-0.038508,1013,944
17,InventoryAndVolatilityAdjusted,BuyPressure,100.032179,99.950000,100.100000,0.005425,-10,1000.370214,0.048424,994,944
18,InventoryAndVolatilityAdjusted,BuyPressure,100.024156,99.950000,100.100000,0.005581,-10,1000.370214,0.128650,981,944
19,InventoryAndVolatilityAdjusted,BuyPressure,100.026929,99.950000,100.100000,0.005412,-10,1000.370214,0.100919,984,944
20,InventoryAndVolatilityAdjusted,BuyPressure,100.043261,99.950000,100.100000,0.006067,0,-0.629786,-0.629786,984,938
21,InventoryAndVolatilityAdjusted,BuyPressure,100.045645,99.969867,100.100000,0.005846,0,-0.629786,-0.629786,994,938
22,InventoryAndVolatilityAdjusted,BuyPressure,100.041056,99.969867,100.100000,0.005771,0,-0.629786,-0.629786,1001,938
23,InventoryAndVolatilityAdjusted,BuyPressure,100.056364,99.969867,100.100000,0.006343,0,-0.629786,-0.629786,1001,924
24,InventoryAndVolatilityAdjusted,BuyPressure,100.053370,100.044191,100.100000,0.006142,0,-0.629786,-0.629786,1021,924
25,InventoryAndVolatilityAdjusted,BuyPressure,100.038593,100.044191,100.100000,0.006660,0,-0.629786,-0.629786,1018,924
26,InventoryAndVolatilityAdjusted,BuyPressure,100.038177,100.044191,100.100000,0.006286,0,-0.629786,-0.629786,1029,924
27,InventoryAndVolatilityAdjusted,BuyPressure,100.023334,100.044191,100.100000,0.006799,0,-0.629786,-0.629786,1021,924
28,InventoryAndVolatilityAdjusted,BuyPressure,100.025431,100.044191,100.100000,0.006517,0,-0.629786,-0.629786,1041,924
29,InventoryAndVolatilityAdjusted,BuyPressure,100.030241,100.044191,100.100000,0.006415,0,-0.629786,-0.629786,1041,932
30,InventoryAndVolatilityAdjusted,BuyPressure,100.016018,99.995360,100.076343,0.006883,0,-0.629786,-0.629786,1040,942
31,InventoryAndVolatilityAdjusted,BuyPressure,100.019513,99.995360,100.076343,0.006680,0,-0.629786,-0.629786,1053,942
32,InventoryAndVolatilityAdjusted,BuyPressure,100.016500,99.995360,100.076343,0.006460,0,-0.629786,-0.629786,1068,942
33,InventoryAndVolatilityAdjusted,BuyPressure,100.012519,99.995360,100.076343,0.006311,0,-0.629786,-0.629786,1085,942
34,InventoryAndVolatilityAdjusted,BuyPressure,100.016963,99.995360,100.076343,0.006199,0,-0.629786,-0.629786,1085,957
35,InventoryAndVolatilityAdjusted,BuyPressure,100.020787,99.995360,100.076343,0.006057,0,-0.629786,-0.629786,1096,957
36,InventoryAndVolatilityAdjusted,BuyPressure,100.032537,99.995360,100.100000,0.006398,-10,1000.133641,-0.191734,1096,938
37,InventoryAndVolatilityAdjusted,BuyPressure,100.040618,99.995360,100.150000,0.006499,-10,1000.133641,-0.272543,1096,930
38,InventoryAndVolatilityAdjusted,BuyPressure,100.039436,99.995360,100.150000,0.006180,-10,1000.133641,-0.260719,1096,946
39,InventoryAndVolatilityAdjusted,BuyPressure,100.053820,99.995360,100.150000,0.006672,-10,1000.133641,-0.404556,1096,945
40,InventoryAndVolatilityAdjusted,BuyPressure,100.041635,100.131130,100.150000,0.007003,-10,1000.133641,-0.282705,1086,955
41,InventoryAndVolatilityAdjusted,BuyPressure,100.039732,100.131130,100.150000,0.006697,-10,1000.133641,-0.263676,1086,972
42,InventoryAndVolatilityAdjusted,BuyPressure,100.024382,99.977829,100.150000,0.007216,0,-1.177658,-1.177658,1075,972
43,InventoryAndVolatilityAdjusted,BuyPressure,100.009011,99.972885,100.150000,0.007706,0,-1.177658,-1.177658,1067,972
44,InventoryAndVolatilityAdjusted,BuyPressure,100.008909,99.972885,100.150000,0.007249,0,-1.177658,-1.177658,1086,972
45,InventoryAndVolatilityAdjusted,BuyPressure,100.011690,99.972885,100.150000,0.006981,0,-1.177658,-1.177658,1092,972
46,InventoryAndVolatilityAdjusted,BuyPressure,100.025630,99.972885,100.150000,0.007399,0,-1.177658,-1.177658,1092,967
47,InventoryAndVolatilityAdjusted,BuyPressure,100.029912,99.972885,100.150000,0.007212,0,-1.177658,-1.177658,1094,967
48,InventoryAndVolatilityAdjusted,BuyPressure,100.031573,99.972885,100.150000,0.006879,0,-1.177658,-1.177658,1113,967
49,InventoryAndVolatilityAdjusted,BuyPressure,100.043862,99.972885,100.150000,0.007203,0,-1.177658,-1.177658,1113,956
50,InventoryAndVolatilityAdjusted,BuyPressure,100.046195,99.985828,100.106562,0.006911,0,-1.177658,-1.177658,1123,979
51,InventoryAndVolatilityAdjusted,BuyPressure,100.055477,99.985828,100.150000,0.007053,-10,999.887960,-0.666814,1123,962
52,InventoryAndVolatilityAdjusted,BuyPressure,100.055999,99.985828,100.150000,0.006662,-10,999.887960,-0.672033,1123,978
53,InventoryAndVolatilityAdjusted,BuyPressure,100.056005,100.039594,100.150000,0.006262,-10,999.887960,-0.672089,1124,978
54,InventoryAndVolatilityAdjusted,BuyPressure,100.071323,100.039594,100.150000,0.006806,-10,999.887960,-0.825273,1124,967
55,InventoryAndVolatilityAdjusted,BuyPressure,100.080152,100.039594,100.150000,0.006927,-10,999.887960,-0.913561,1124,964
56,InventoryAndVolatilityAdjusted,BuyPressure,100.078316,100.049926,100.150000,0.006621,-10,999.887960,-0.895204,1132,964
57,InventoryAndVolatilityAdjusted,BuyPressure,100.063788,99.985828,100.150000,0.007096,-7,699.930475,-0.516039,1120,964
58,InventoryAndVolatilityAdjusted,BuyPressure,100.074650,99.985828,100.164764,0.007322,-7,699.930475,-0.592072,1120,950
59,InventoryAndVolatilityAdjusted,BuyPressure,100.072741,99.985828,100.164764,0.006997,-7,699.930475,-0.578714,1130,950
60,InventoryAndVolatilityAdjusted,BuyPressure,100.079900,100.124390,100.173528,0.007007,-7,699.930475,-0.628826,1140,951
61,InventoryAndVolatilityAdjusted,BuyPressure,100.093470,100.124390,100.179234,0.007401,-7,699.930475,-0.723816,1140,941
62,InventoryAndVolatilityAdjusted,BuyPressure,100.105114,100.124390,100.200000,0.007655,-7,699.930475,-0.805324,1140,928
63,InventoryAndVolatilityAdjusted,BuyPressure,100.105351,100.124390,100.200000,0.007210,-7,699.930475,-0.806980,1145,928
64,InventoryAndVolatilityAdjusted,BuyPressure,100.092511,100.124390,100.200000,0.007548,-4,399.557305,-0.812740,1142,928
65,InventoryAndVolatilityAdjusted,BuyPressure,100.089047,100.124390,100.200000,0.007303,-4,399.557305,-0.798881,1158,928
66,InventoryAndVolatilityAdjusted,BuyPressure,100.089948,100.124390,100.138831,0.006919,-4,399.557305,-0.802486,1158,944
67,InventoryAndVolatilityAdjusted,BuyPressure,100.090931,99.985828,100.111603,0.006563,3,-301.313425,-1.040632,1151,947
